Workbook

Sheet Assumptions
A1: MOTILAL OSWAL -- ASSUMPTIONS & KEY DRIVERS
A2: Driver | B2: FY2022A | C2: FY2023A | D2: FY2024A | E2: FY2025A | F2: FY2026E | G2: FY2027E | H2: FY2028E | I2: FY2029E
A3: REVENUE ASSUMPTIONS
A4: Revenue Growth Rate (%) | B4: 0.041 | C4: 0.355 | D4: 0.245 | E4: 0.245 | F4: 0.18 | G4: 0.15 | H4: 0.12 | I4: 0.1
A5: MARGIN ASSUMPTIONS
A6: EBITDA Margin (%) | B6: 0.577 | C6: 0.488 | D6: 0.795 | E6: 0.711 | F6: 0.68 | G6: 0.7 | H6: 0.72 | I6: 0.72
A7: Net Income Margin (%) | B7: 0.357 | C7: 0.18 | D7: 0.472 | E7: 0.388 | F7: 0.4 | G7: 0.41 | H7: 0.42 | I7: 0.42
A8: Tax Rate (%) | B8: 0.25 | C8: 0.25 | D8: 0.25 | E8: 0.25 | F8: 0.25 | G8: 0.25 | H8: 0.25 | I8: 0.25
A10: DCF ASSUMPTIONS
A11: WACC (%) | B11: 0.14
A12: Risk Free Rate (%) | B12: 0.071
A13: Equity Risk Premium (%) | B13: 0.075
A14: Beta | B14: 1.15
A15: Terminal Growth Rate (%) | B15: 0.05
A16: Net Debt (Rs Cr) | B16: 8138
A17: Shares Outstanding (Cr) | B17: 14.4
A19: LBO ASSUMPTIONS
A20: Entry EV/EBITDA Multiple (x) | B20: 10
A21: Exit EV/EBITDA Multiple (x) | B21: 12
A22: Debt % of Entry EV | B22: 0.5
A23: Senior Debt % of Total Debt | B23: 0.7
A24: Mezz Debt % of Total Debt | B24: 0.3
A25: Senior Interest Rate (%) | B25: 0.09
A26: Mezz Interest Rate (%) | B26: 0.13
A27: Amortisation (% of debt/yr) | B27: 0.05
A28: Holding Period (years) | B28: 5

Sheet 3-Statement
A1: THREE-STATEMENT MODEL -- MOTILAL OSWAL (Rs Crores)
B2: FY2022A | C2: FY2023A | D2: FY2024A | E2: FY2025A | F2: FY2026E | G2: FY2027E | H2: FY2028E | I2: FY2029E
A3: INCOME STATEMENT
A4: Total Revenue | B4: 3818.9 | C4: 5174.4 | D4: 6441.8 | E4: 6441.8 | F4: =E4*(1+Assumptions!B4) | G4: =F4*(1+Assumptions!B4) | H4: =G4*(1+Assumptions!B4) | I4: =H4*(1+Assumptions!B4)
A5: Gross Profit | B5: --- | C5: 2032.9 | D5: 2791.7 | E5: 3526.5 | F5: --- | G5: --- | H5: --- | I5: ---
A6: EBITDA | B6: 1862.5 | C6: 4115 | D6: 4578.3 | E6: 4578.3 | F6: =F4*Assumptions!B6 | G6: =G4*Assumptions!B6 | H6: =H4*Assumptions!B6 | I6: =I4*Assumptions!B6
A7: EBIT | B7: 1804.1 | C7: 4032.5 | D7: 4479.5 | E7: 4479.5 | F7: --- | G7: --- | H7: --- | I7: ---
A8: Net Income | B8: 931.1 | C8: 2441.1 | D8: 2501.6 | E8: 2501.6 | F8: =F6*Assumptions!B7 | G8: =G6*Assumptions!B7 | H8: =H6*Assumptions!B7 | I8: =I6*Assumptions!B7
A10: BALANCE SHEET
A11: Total Assets | B11: 23009.9 | C11: 31829.2 | D11: 33987.1 | E11: 33987.1 | F11: --- | G11: --- | H11: --- | I11: ---
A12: Cash & Equivalents | B12: 2576.3 | C12: 5285.7 | D12: 6592.5 | E12: 6592.5 | F12: --- | G12: --- | H12: --- | I12: ---
A13: Total Debt | B13: 10275.9 | C13: 13745.6 | D13: 14731.6 | E13: 14731.6 | F13: --- | G13: --- | H13: --- | I13: ---
A14: Stockholders Equity | B14: 6252.2 | C14: 8731.8 | D14: 11079.3 | E14: 11079.3 | F14: --- | G14: --- | H14: --- | I14: ---
A16: CASH FLOW STATEMENT
A17: Operating Cash Flow | B17: -3057.9 | C17: -349.6 | D17: 1214.6 | E17: 1214.6 | F17: --- | G17: --- | H17: --- | I17: ---
A18: Capital Expenditure | B18: -153.8 | C18: -150.8 | D18: -284.3 | E18: -284.3 | F18: --- | G18: --- | H18: --- | I18: ---
A19: Free Cash Flow | B19: -3211.7 | C19: -500.4 | D19: 930.4 | E19: 930.4 | F19: --- | G19: --- | H19: --- | I19: ---
A20: Financing Cash Flow | B20: 3770.4 | C20: 3305.8 | D20: 745.1 | E20: 745.1 | F20: --- | G20: --- | H20: --- | I20: ---

Sheet DCF
A1: DCF VALUATION -- MOTILAL OSWAL (Rs Crores)
B2: FY2026E | C2: FY2027E | D2: FY2028E
A3: STEP 1 -- UNLEVERED FREE CASH FLOW (UFCF)
A4: EBITDA (from 3-Stmt) | B4: ='3-Statement'!F6 | C4: ='3-Statement'!G6 | D4: ='3-Statement'!H6
A5: (-) Tax on EBIT (25%) | B5: =-B4*Assumptions!B8 | C5: =-C4*Assumptions!B8 | D5: =-D4*Assumptions!B8
A6: NOPAT | B6: =B4+B5 | C6: =C4+C5 | D6: =D4+D5
A7: (+) D&A est. (2% Rev) | B7: ='3-Statement'!F4*0.02 | C7: ='3-Statement'!G4*0.02 | D7: ='3-Statement'!H4*0.02
A8: (-) Capex (2% Rev) | B8: =-'3-Statement'!F4*0.02 | C8: =-'3-Statement'!G4*0.02 | D8: =-'3-Statement'!H4*0.02
A9: (-) Change in NWC (3%) | B9: =-'3-Statement'!F4*0.03 | C9: =-'3-Statement'!G4*0.03 | D9: =-'3-Statement'!H4*0.03
A10: Unlevered Free Cash Flow | B10: =B6+B7+B8+B9 | C10: =C6+C7+C8+C9 | D10: =D6+D7+D8+D9
A12: STEP 2 -- DISCOUNT FACTORS & PRESENT VALUES
A13: Discount Period (mid-year) | B13: 0.5 | C13: 1.5 | D13: 2.5
A14: Discount Factor | B14: =1/(1+Assumptions!B11)^B13 | C14: =1/(1+Assumptions!B11)^C13 | D14: =1/(1+Assumptions!B11)^D13
A15: PV of UFCF | B15: =B10*B14 | C15: =C10*C14 | D15: =D10*D14
A17: STEP 3 -- TERMINAL VALUE (GORDON GROWTH)
A18: Terminal Year UFCF (FY2028E) | B18: =D10
A19: Terminal Growth Rate (g) | B19: =Assumptions!B15
A20: WACC | B20: =Assumptions!B11
A21: Terminal Value = UFCF*(1+g)/(WACC-g) | B21: =B18*(1+B19)/(B20-B19)
A22: PV of Terminal Value | B22: =B21/(1+Assumptions!B11)^2.5
A24: STEP 4 -- ENTERPRISE VALUE TO EQUITY VALUE
A25: Sum of PV of UFCFs | B25: =SUM(B15:D15)
A26: (+) PV of Terminal Value | B26: =B22
A27: Enterprise Value (EV) | B27: =B25+B26
A28: (-) Net Debt | B28: =Assumptions!B16
A29: Equity Value | B29: =B27-B28
A30: Shares Outstanding (Cr) | B30: =Assumptions!B17
A31: Implied Share Price (Rs) | B31: =B29/B30
A33: STEP 5 -- SENSITIVITY: WACC vs TERMINAL GROWTH
A34: Share Price WACC vs TGR | B34: 0.03 | C34: 0.04 | D34: 0.05 | E34: 0.06 | F34: 0.07
A35: 0.12 | B35: 153891 | C35: 176676 | D35: 205970 | E35: 245029 | F35: 299711
A36: 0.13 | B36: 133813 | C36: 151799 | D36: 174282 | E36: 203188 | F36: 241729
A37: 0.14 | B37: 117477 | C37: 132000 | D37: 149750 | E37: 171937 | F37: 200464
A38: 0.15 | B38: 103945 | C38: 115890 | D38: 130223 | E38: 147742 | F38: 169641
A39: 0.16 | B39: 92567 | C39: 102543 | D39: 114334 | E39: 128482 | F39: 145775

Sheet LBO
A1: LBO MODEL -- MOTILAL OSWAL (Rs Crores)
A3: TRANSACTION ASSUMPTIONS
A4: Entry EBITDA (FY2026E, Rs Cr) | B4: 3869
A5: Entry EV/EBITDA Multiple (x) | B5: 10
A6: Entry Enterprise Value (Rs Cr) | B6: =B4*B5
A7: (-) Equity Contribution (50%) | B7: =B6*0.50
A8: (+) Total Debt (50%) | B8: =B6*0.50
A9: Senior Debt (70% of debt) | B9: =B8*0.70
A10: Mezz Debt (30% of debt) | B10: =B8*0.30
A11: Senior Interest Rate (%) | B11: 0.09
A12: Mezz Interest Rate (%) | B12: 0.13
A13: Amortisation (% of debt/yr) | B13: 0.05
A15: 5-YEAR PROJECTIONS
B16: FY2026E | C16: FY2027E | D16: FY2028E | E16: FY2029E | F16: FY2030E
A17: Revenue (Rs Cr) | B17: ='3-Statement'!F4 | C17: ='3-Statement'!G4 | D17: ='3-Statement'!H4 | E17: =E17*1.10 | F17: =F17*1.10
A18: EBITDA (Rs Cr) | B18: ='3-Statement'!F6 | C18: ='3-Statement'!G6 | D18: ='3-Statement'!H6 | E18: =E18*1.10 | F18: =F18*1.10
A19: EBITDA Margin (%) | B19: =B18/B17 | C19: =C18/C17 | D19: =D18/D17 | E19: =E18/E17 | F19: =F18/F17
A21: DEBT SCHEDULE
B22: FY2026E | C22: FY2027E | D22: FY2028E | E22: FY2029E | F22: FY2030E
A23: Opening Total Debt | B23: =B8 | C23: =B25 | D23: =C25 | E23: =D25 | F23: =E25
A24: (-) Amortisation | B24: =-B23*B13 | C24: =-C23*B13 | D24: =-D23*B13 | E24: =-E23*B13 | F24: =-F23*B13
A25: Closing Total Debt | B25: =B23+B24 | C25: =C23+C24 | D25: =D23+D24 | E25: =E23+E24 | F25: =F23+F24
A26: Senior Interest | B26: =-B23*0.70*B11 | C26: =-C23*0.70*B11 | D26: =-D23*0.70*B11 | E26: =-E23*0.70*B11 | F26: =-F23*0.70*B11
A27: Mezz Interest | B27: =-B23*0.30*B12 | C27: =-C23*0.30*B12 | D27: =-D23*0.30*B12 | E27: =-E23*0.30*B12 | F27: =-F23*0.30*B12
A28: Total Interest Expense | B28: =B26+B27 | C28: =C26+C27 | D28: =D26+D27 | E28: =E26+E27 | F28: =F26+F27
A30: FREE CASH FLOW
B31: FY2026E | C31: FY2027E | D31: FY2028E | E31: FY2029E | F31: FY2030E
A32: EBITDA | B32: =B18 | C32: =C18 | D32: =D18 | E32: =E18 | F32: =F18
A33: (-) Interest | B33: =B28 | C33: =C28 | D33: =D28 | E33: =E28 | F33: =F28
A34: (-) Tax (25%) | B34: =-(B32+B33)*0.25 | C34: =-(C32+C33)*0.25 | D34: =-(D32+D33)*0.25 | E34: =-(E32+E33)*0.25 | F34: =-(F32+F33)*0.25
A35: (-) Capex (2% Rev) | B35: =-B17*0.02 | C35: =-C17*0.02 | D35: =-D17*0.02 | E35: =-E17*0.02 | F35: =-F17*0.02
A36: (-) Amortisation | B36: =B24 | C36: =C24 | D36: =D24 | E36: =E24 | F36: =F24
A37: Free Cash Flow | B37: =B32+B33+B34+B35+B36 | C37: =C32+C33+C34+C35+C36 | D37: =D32+D33+D34+D35+D36 | E37: =E32+E33+E34+E35+E36 | F37: =F32+F33+F34+F35+F36
A39: EXIT ASSUMPTIONS & RETURNS
A40: Exit Year | B40: 5
A41: Exit EBITDA (FY2030E, Rs Cr) | B41: ='3-statement'!H6*1.10*1.10
A42: Exit EV/EBITDA Multiple (x) | B42: 12
A43: Exit Enterprise Value (Rs Cr) | B43: =B41*B42
A44: (-) Closing Debt at Exit | B44: =F25
A45: Equity Value at Exit (Rs Cr) | B45: =B43-B44
...

Sheet Comps
A1: COMPARABLE COMPANIES ANALYSIS -- INDIAN IB SECTOR (Rs Crores)
A2: Company | B2: Mkt Cap | C2: EV | D2: Revenue | E2: EBITDA | F2: Net Income | G2: EV/EBITDA | H2: P/E
A3: PEER GROUP — INDIAN INVESTMENT BANKS
A4: Motilal Oswal (Target) | B4: 42368 | C4: 50506 | D4: 6441 | E4: 4578 | F4: 2501 | G4: 11 | H4: 16.9
A5: Nuvama Wealth Mgmt | B5: 25532 | C5: 27800 | D5: 3200 | E5: 1920 | F5: 1100 | G5: 14.5 | H5: 23.2
A6: JM Financial | B6: 8200 | C6: 9800 | D6: 2100 | E6: 840 | F6: 520 | G6: 11.7 | H6: 15.8
A7: IIFL Capital Services | B7: 9800 | C7: 11200 | D7: 2800 | E7: 1120 | F7: 650 | G7: 10 | H7: 15.1
A8: Anand Rathi Wealth | B8: 25532 | C8: 25800 | D8: 1850 | E8: 1110 | F8: 780 | G8: 23.2 | H8: 32.7
A10: PEER STATISTICS
A11: Mean | B11: =AVERAGE(B5:B8) | C11: =AVERAGE(C5:C8) | D11: =AVERAGE(D5:D8) | E11: =AVERAGE(E5:E8) | F11: =AVERAGE(F5:F8) | G11: =AVERAGE(G5:G8) | H11: =AVERAGE(H5:H8)
A12: Median | B12: =MEDIAN(B5:B8) | C12: =MEDIAN(C5:C8) | D12: =MEDIAN(D5:D8) | E12: =MEDIAN(E5:E8) | F12: =MEDIAN(F5:F8) | G12: =MEDIAN(G5:G8) | H12: =MEDIAN(H5:H8)
A13: High | B13: =MAX(B5:B8) | C13: =MAX(C5:C8) | D13: =MAX(D5:D8) | E13: =MAX(E5:E8) | F13: =MAX(F5:F8) | G13: =MAX(G5:G8) | H13: =MAX(H5:H8)
A14: Low | B14: =MIN(B5:B8) | C14: =MIN(C5:C8) | D14: =MIN(D5:D8) | E14: =MIN(E5:E8) | F14: =MIN(F5:F8) | G14: =MIN(G5:G8) | H14: =MIN(H5:H8)
A16: IMPLIED VALUATION OF MOTILAL OSWAL
A17: Metric | B17: Multiple Used | C17: MOFSL Metric | D17: Implied EV | E17: (-) Net Debt | F17: Equity Value | G17: Implied Price | H17: vs DCF
A18: EV/EBITDA — Mean | B18: =H11 | C18: ='3-Statement'!F6 | D18: =B18*C18 | E18: =Assumptions!B16 | F18: =D18-E18 | G18: =F18/Assumptions!B17*100 | H18: =G18/DCF!B31-1
A19: EV/EBITDA — Median | B19: =H12 | C19: ='3-Statement'!F6 | D19: =B19*C19 | E19: =Assumptions!B16 | F19: =D19-E19 | G19: =F19/Assumptions!B17*100 | H19: =G19/DCF!B31-1
A20: EV/EBITDA — High | B20: =H13 | C20: ='3-Statement'!F6 | D20: =B20*C20 | E20: =Assumptions!B16 | F20: =D20-E20 | G20: =F20/Assumptions!B17*100 | H20: =G20/DCF!B31-1
A21: EV/EBITDA — Low | B21: =H14 | C21: ='3-Statement'!F6 | D21: =B21*C21 | E21: =Assumptions!B16 | F21: =D21-E21 | G21: =F21/Assumptions!B17*100 | H21: =G21/DCF!B31-1
A24: KEY METRICS SUMMARY
A25: Company | B25: Revenue Gr% | C25: EBITDA Mgn% | D25: Net Inc Mgn% | E25: EV/EBITDA | F25: P/E | G25: Mkt Cap | H25: Rating
A26: Motilal Oswal | B26: 0.245 | C26: 0.711 | D26: 0.388 | E26: 11 | F26: 16.9 | G26: 42368 | H26: TARGET
A27: Nuvama Wealth | B27: 0.18 | C27: 0.6 | D27: 0.344 | E27: 14.5 | F27: 23.2 | G27: 25532 | H27: COMP
A28: JM Financial | B28: 0.15 | C28: 0.4 | D28: 0.248 | E28: 11.7 | F28: 15.8 | G28: 8200 | H28: COMP
A29: IIFL Capital | B29: 0.2 | C29: 0.4 | D29: 0.232 | E29: 10 | F29: 15.1 | G29: 9800 | H29: COMP
A30: Anand Rathi | B30: 0.22 | C30: 0.6 | D30: 0.422 | E30: 23.2 | F30: 32.7 | G30: 25532 | H30: COMP

Sheet Football Field
A1: FOOTBALL FIELD VALUATION SUMMARY -- MOTILAL OSWAL
A2: Implied Share Price (Rs) across all valuation methodologies
A4: STEP 1 -- VALUATION RANGE INPUTS (Rs per share)
A5: Methodology | B5: Low | C5: Mid | D5: High | E5: Weight | F5: Wtd Low | G5: Wtd Mid | H5: Wtd High | I5: Notes
A6: DCF Valuation | B6: =DCF!B31*0.85 | C6: =DCF!B31 | D6: =DCF!B31*1.15 | E6: 0.35 | F6: =B6*E6 | G6: =C6*E6 | H6: =D6*E6 | I6: WACC 14%, TGR 5%, 3-yr projection
A7: EV/EBITDA Comps — Low | B7: =Comps!G21 | C7: =Comps!G19 | D7: =Comps!G18 | E7: 0.25 | F7: =B7*E7 | G7: =C7*E7 | H7: =D7*E7 | I7: Peer group: NUVAMA, JM, IIFL, ANAND RATHI
A8: LBO Floor Valuation | B8: =LBO!B45/Assumptions!B17*100*0.90 | C8: =LBO!B45/Assumptions!B17*100 | D8: =LBO!B45/Assumptions!B17*100*1.10 | E8: 0.2 | F8: =B8*E8 | G8: =C8*E8 | H8: =D8*E8 | I8: PE entry 10x, exit 12x, 5yr, 18.9% IRR
A9: 52-Week Trading Range | B9: 800 | C9: 1100 | D9: 1400 | E9: 0.1 | F9: =B9*E9 | G9: =C9*E9 | H9: =D9*E9 | I9: NSE 52W Low-High range
A10: Book Value (P/BV 3-4x) | B10: =Assumptions!B17*0+11079.3/14.4*100*3 | C10: =Assumptions!B17*0+11079.3/14.4*100*3.5 | D10: =Assumptions!B17*0+11079.3/14.4*100*4 | E10: 0.1 | F10: =B10*E10 | G10: =C10*E10 | H10: =D10*E10 | I10: Equity Rs 11,079 Cr, 14.4 Cr shares
A11: WEIGHTED AVERAGE | B11: --- | C11: --- | D11: --- | E11: =SUM(E6:E10) | F11: =SUM(F6:F10) | G11: =SUM(G6:G10) | H11: =SUM(H6:H10)
A13: STEP 2 -- FOOTBALL FIELD CHART (Visual Range)
A15: Methodology | B15: Rs200 | C15: Rs400 | D15: Rs600 | E15: Rs800 | F15: Rs1000 | G15: Rs1200 | H15: Rs1400 | I15: Rs1600 | J15: Rs1800
A16: DCF
A17: EV/EBITDA Comps
A18: LBO Floor
A19: 52-Week Range
A20: P/Book Value
A22: Current Market Price ~Rs 768 (as of data fetch) | 52W High Rs 1,064 | 52W Low Rs 612
A24: STEP 3 -- FINAL VALUATION CONCLUSION
A25: Weighted Average Low (Rs) | B25: =F11
A26: Weighted Average Mid (Rs) | B26: =G11
A27: Weighted Average High (Rs) | B27: =H11
A28: Current Market Price (Rs) | B28: 768
A29: Upside to Mid (Wtd Avg) | B29: =B26/B28-1
A30: Analyst Rating | B30: BUY
